[2024-04-07T01:59:24.273+0000] {taskinstance.py:1957} INFO - Dependencies all met for dep_context=non-requeueable deps ti=<TaskInstance: defi_data_pipeline.insert_data_into_db scheduled__2024-04-07T00:01:00+00:00 [queued]>
[2024-04-07T01:59:24.752+0000] {taskinstance.py:1957} INFO - Dependencies all met for dep_context=requeueable deps ti=<TaskInstance: defi_data_pipeline.insert_data_into_db scheduled__2024-04-07T00:01:00+00:00 [queued]>
[2024-04-07T01:59:24.752+0000] {taskinstance.py:2171} INFO - Starting attempt 1 of 1
[2024-04-07T01:59:24.786+0000] {taskinstance.py:2192} INFO - Executing <Task(_PythonDecoratedOperator): insert_data_into_db> on 2024-04-07 00:01:00+00:00
[2024-04-07T01:59:24.793+0000] {standard_task_runner.py:60} INFO - Started process 22528 to run task
[2024-04-07T01:59:24.799+0000] {standard_task_runner.py:87} INFO - Running: ['***', 'tasks', 'run', 'defi_data_pipeline', 'insert_data_into_db', 'scheduled__2024-04-07T00:01:00+00:00', '--job-id', '341', '--raw', '--subdir', 'DAGS_FOLDER/_etl.py', '--cfg-path', '/tmp/tmp3fo2qcz1']
[2024-04-07T01:59:24.803+0000] {standard_task_runner.py:88} INFO - Job 341: Subtask insert_data_into_db
[2024-04-07T01:59:24.829+0000] {logging_mixin.py:188} WARNING - /home/***/.local/lib/python3.8/site-packages/***/settings.py:195 DeprecationWarning: The sql_alchemy_conn option in [core] has been moved to the sql_alchemy_conn option in [database] - the old setting has been used, but please update your config.
[2024-04-07T01:59:24.889+0000] {task_command.py:423} INFO - Running <TaskInstance: defi_data_pipeline.insert_data_into_db scheduled__2024-04-07T00:01:00+00:00 [running]> on host aa86d21a7ebc
[2024-04-07T01:59:25.137+0000] {taskinstance.py:2481} INFO - Exporting env vars: AIRFLOW_CTX_DAG_OWNER='***' AIRFLOW_CTX_DAG_ID='defi_data_pipeline' AIRFLOW_CTX_TASK_ID='insert_data_into_db' AIRFLOW_CTX_EXECUTION_DATE='2024-04-07T00:01:00+00:00' AIRFLOW_CTX_TRY_NUMBER='1' AIRFLOW_CTX_DAG_RUN_ID='scheduled__2024-04-07T00:01:00+00:00'
[2024-04-07T01:59:25.139+0000] {taskinstance.py:2699} ERROR - Task failed with exception
Traceback (most recent call last):
  File "/home/airflow/.local/lib/python3.8/site-packages/airflow/models/taskinstance.py", line 433, in _execute_task
    result = execute_callable(context=context, **execute_callable_kwargs)
  File "/home/airflow/.local/lib/python3.8/site-packages/airflow/decorators/base.py", line 242, in execute
    return_value = super().execute(context)
  File "/home/airflow/.local/lib/python3.8/site-packages/airflow/operators/python.py", line 199, in execute
    return_value = self.execute_callable()
  File "/home/airflow/.local/lib/python3.8/site-packages/airflow/operators/python.py", line 216, in execute_callable
    return self.python_callable(*self.op_args, **self.op_kwargs)
  File "/opt/airflow/dags/_etl.py", line 80, in insert_data_into_db
    transform_data = ti.xcom_pull(key='transform_data', task_ids='transform_data')
NameError: name 'ti' is not defined
[2024-04-07T01:59:25.157+0000] {taskinstance.py:1138} INFO - Marking task as FAILED. dag_id=defi_data_pipeline, task_id=insert_data_into_db, execution_date=20240407T000100, start_date=20240407T015924, end_date=20240407T015925
[2024-04-07T01:59:25.172+0000] {standard_task_runner.py:107} ERROR - Failed to execute job 341 for task insert_data_into_db (name 'ti' is not defined; 22528)
[2024-04-07T01:59:25.185+0000] {local_task_job_runner.py:234} INFO - Task exited with return code 1
[2024-04-07T01:59:25.205+0000] {taskinstance.py:3281} INFO - 0 downstream tasks scheduled from follow-on schedule check
