[2024-04-07T13:05:37.170+0000] {taskinstance.py:1957} INFO - Dependencies all met for dep_context=non-requeueable deps ti=<TaskInstance: defi_data_pipeline.establish_database_conn scheduled__2024-04-07T12:01:00+00:00 [queued]>
[2024-04-07T13:05:37.217+0000] {taskinstance.py:1957} INFO - Dependencies all met for dep_context=requeueable deps ti=<TaskInstance: defi_data_pipeline.establish_database_conn scheduled__2024-04-07T12:01:00+00:00 [queued]>
[2024-04-07T13:05:37.217+0000] {taskinstance.py:2171} INFO - Starting attempt 1 of 1
[2024-04-07T13:05:37.977+0000] {taskinstance.py:2192} INFO - Executing <Task(_PythonDecoratedOperator): establish_database_conn> on 2024-04-07 12:01:00+00:00
[2024-04-07T13:05:38.004+0000] {standard_task_runner.py:60} INFO - Started process 38934 to run task
[2024-04-07T13:05:38.024+0000] {standard_task_runner.py:87} INFO - Running: ['***', 'tasks', 'run', 'defi_data_pipeline', 'establish_database_conn', 'scheduled__2024-04-07T12:01:00+00:00', '--job-id', '402', '--raw', '--subdir', 'DAGS_FOLDER/_etl.py', '--cfg-path', '/tmp/tmpkywfhlbe']
[2024-04-07T13:05:38.039+0000] {standard_task_runner.py:88} INFO - Job 402: Subtask establish_database_conn
[2024-04-07T13:05:38.106+0000] {logging_mixin.py:188} WARNING - /home/***/.local/lib/python3.8/site-packages/***/settings.py:195 DeprecationWarning: The sql_alchemy_conn option in [core] has been moved to the sql_alchemy_conn option in [database] - the old setting has been used, but please update your config.
[2024-04-07T13:05:38.222+0000] {logging_mixin.py:188} INFO - Changing /opt/***/logs/dag_id=defi_data_pipeline/run_id=scheduled__2024-04-07T12:01:00+00:00/task_id=establish_database_conn permission to 509
[2024-04-07T13:05:38.228+0000] {task_command.py:423} INFO - Running <TaskInstance: defi_data_pipeline.establish_database_conn scheduled__2024-04-07T12:01:00+00:00 [running]> on host aa86d21a7ebc
[2024-04-07T13:05:39.255+0000] {taskinstance.py:2481} INFO - Exporting env vars: AIRFLOW_CTX_DAG_OWNER='***' AIRFLOW_CTX_DAG_ID='defi_data_pipeline' AIRFLOW_CTX_TASK_ID='establish_database_conn' AIRFLOW_CTX_EXECUTION_DATE='2024-04-07T12:01:00+00:00' AIRFLOW_CTX_TRY_NUMBER='1' AIRFLOW_CTX_DAG_RUN_ID='scheduled__2024-04-07T12:01:00+00:00'
[2024-04-07T13:05:39.283+0000] {base.py:83} INFO - Using connection ID 'defi_connection' for task execution.
[2024-04-07T13:05:39.299+0000] {taskinstance.py:2699} ERROR - Task failed with exception
Traceback (most recent call last):
  File "/home/airflow/.local/lib/python3.8/site-packages/airflow/models/taskinstance.py", line 433, in _execute_task
    result = execute_callable(context=context, **execute_callable_kwargs)
  File "/home/airflow/.local/lib/python3.8/site-packages/airflow/decorators/base.py", line 242, in execute
    return_value = super().execute(context)
  File "/home/airflow/.local/lib/python3.8/site-packages/airflow/operators/python.py", line 199, in execute
    return_value = self.execute_callable()
  File "/home/airflow/.local/lib/python3.8/site-packages/airflow/operators/python.py", line 216, in execute_callable
    return self.python_callable(*self.op_args, **self.op_kwargs)
  File "/opt/airflow/dags/_etl.py", line 107, in establish_database_conn
    cursor.execute(qry, (record))
psycopg2.errors.UndefinedTable: relation "token" does not exist
LINE 2:         INSERT INTO token (
                            ^

[2024-04-07T13:05:39.365+0000] {taskinstance.py:1138} INFO - Marking task as FAILED. dag_id=defi_data_pipeline, task_id=establish_database_conn, execution_date=20240407T120100, start_date=20240407T130537, end_date=20240407T130539
[2024-04-07T13:05:39.422+0000] {standard_task_runner.py:107} ERROR - Failed to execute job 402 for task establish_database_conn (relation "token" does not exist
LINE 2:         INSERT INTO token (
                            ^
; 38934)
[2024-04-07T13:05:39.503+0000] {local_task_job_runner.py:234} INFO - Task exited with return code 1
[2024-04-07T13:05:39.544+0000] {taskinstance.py:3281} INFO - 0 downstream tasks scheduled from follow-on schedule check
[2024-04-07T13:10:46.217+0000] {taskinstance.py:1957} INFO - Dependencies all met for dep_context=non-requeueable deps ti=<TaskInstance: defi_data_pipeline.establish_database_conn scheduled__2024-04-07T12:01:00+00:00 [queued]>
[2024-04-07T13:10:46.245+0000] {taskinstance.py:1957} INFO - Dependencies all met for dep_context=requeueable deps ti=<TaskInstance: defi_data_pipeline.establish_database_conn scheduled__2024-04-07T12:01:00+00:00 [queued]>
[2024-04-07T13:10:46.245+0000] {taskinstance.py:2171} INFO - Starting attempt 1 of 1
[2024-04-07T13:10:46.704+0000] {taskinstance.py:2192} INFO - Executing <Task(_PythonDecoratedOperator): establish_database_conn> on 2024-04-07 12:01:00+00:00
[2024-04-07T13:10:46.718+0000] {standard_task_runner.py:60} INFO - Started process 39254 to run task
[2024-04-07T13:10:46.733+0000] {standard_task_runner.py:87} INFO - Running: ['***', 'tasks', 'run', 'defi_data_pipeline', 'establish_database_conn', 'scheduled__2024-04-07T12:01:00+00:00', '--job-id', '406', '--raw', '--subdir', 'DAGS_FOLDER/_etl.py', '--cfg-path', '/tmp/tmpc9fukgri']
[2024-04-07T13:10:46.744+0000] {standard_task_runner.py:88} INFO - Job 406: Subtask establish_database_conn
[2024-04-07T13:10:46.786+0000] {logging_mixin.py:188} WARNING - /home/***/.local/lib/python3.8/site-packages/***/settings.py:195 DeprecationWarning: The sql_alchemy_conn option in [core] has been moved to the sql_alchemy_conn option in [database] - the old setting has been used, but please update your config.
[2024-04-07T13:10:46.884+0000] {task_command.py:423} INFO - Running <TaskInstance: defi_data_pipeline.establish_database_conn scheduled__2024-04-07T12:01:00+00:00 [running]> on host aa86d21a7ebc
[2024-04-07T13:10:47.350+0000] {taskinstance.py:2481} INFO - Exporting env vars: AIRFLOW_CTX_DAG_OWNER='***' AIRFLOW_CTX_DAG_ID='defi_data_pipeline' AIRFLOW_CTX_TASK_ID='establish_database_conn' AIRFLOW_CTX_EXECUTION_DATE='2024-04-07T12:01:00+00:00' AIRFLOW_CTX_TRY_NUMBER='1' AIRFLOW_CTX_DAG_RUN_ID='scheduled__2024-04-07T12:01:00+00:00'
[2024-04-07T13:10:47.399+0000] {base.py:83} INFO - Using connection ID 'defi_connection' for task execution.
[2024-04-07T13:10:47.414+0000] {taskinstance.py:2699} ERROR - Task failed with exception
Traceback (most recent call last):
  File "/home/airflow/.local/lib/python3.8/site-packages/airflow/models/taskinstance.py", line 433, in _execute_task
    result = execute_callable(context=context, **execute_callable_kwargs)
  File "/home/airflow/.local/lib/python3.8/site-packages/airflow/decorators/base.py", line 242, in execute
    return_value = super().execute(context)
  File "/home/airflow/.local/lib/python3.8/site-packages/airflow/operators/python.py", line 199, in execute
    return_value = self.execute_callable()
  File "/home/airflow/.local/lib/python3.8/site-packages/airflow/operators/python.py", line 216, in execute_callable
    return self.python_callable(*self.op_args, **self.op_kwargs)
  File "/opt/airflow/dags/_etl.py", line 107, in establish_database_conn
    cursor.execute(qry, (record))
psycopg2.errors.UndefinedTable: relation "token" does not exist
LINE 2:         INSERT INTO token (
                            ^

[2024-04-07T13:10:47.447+0000] {taskinstance.py:1138} INFO - Marking task as FAILED. dag_id=defi_data_pipeline, task_id=establish_database_conn, execution_date=20240407T120100, start_date=20240407T131046, end_date=20240407T131047
[2024-04-07T13:10:47.506+0000] {standard_task_runner.py:107} ERROR - Failed to execute job 406 for task establish_database_conn (relation "token" does not exist
LINE 2:         INSERT INTO token (
                            ^
; 39254)
[2024-04-07T13:10:47.582+0000] {local_task_job_runner.py:234} INFO - Task exited with return code 1
[2024-04-07T13:10:47.979+0000] {taskinstance.py:3281} INFO - 0 downstream tasks scheduled from follow-on schedule check
