[2024-04-06T23:01:04.899+0000] {taskinstance.py:1957} INFO - Dependencies all met for dep_context=non-requeueable deps ti=<TaskInstance: defi_data_pipeline.transform_to_add_datetime scheduled__2024-04-06T22:01:00+00:00 [queued]>
[2024-04-06T23:01:04.913+0000] {taskinstance.py:1957} INFO - Dependencies all met for dep_context=requeueable deps ti=<TaskInstance: defi_data_pipeline.transform_to_add_datetime scheduled__2024-04-06T22:01:00+00:00 [queued]>
[2024-04-06T23:01:04.913+0000] {taskinstance.py:2171} INFO - Starting attempt 1 of 1
[2024-04-06T23:01:05.197+0000] {taskinstance.py:2192} INFO - Executing <Task(_PythonDecoratedOperator): transform_to_add_datetime> on 2024-04-06 22:01:00+00:00
[2024-04-06T23:01:05.204+0000] {standard_task_runner.py:60} INFO - Started process 13075 to run task
[2024-04-06T23:01:05.208+0000] {standard_task_runner.py:87} INFO - Running: ['***', 'tasks', 'run', 'defi_data_pipeline', 'transform_to_add_datetime', 'scheduled__2024-04-06T22:01:00+00:00', '--job-id', '321', '--raw', '--subdir', 'DAGS_FOLDER/_etl.py', '--cfg-path', '/tmp/tmppfukvm6j']
[2024-04-06T23:01:05.211+0000] {standard_task_runner.py:88} INFO - Job 321: Subtask transform_to_add_datetime
[2024-04-06T23:01:05.239+0000] {logging_mixin.py:188} WARNING - /home/***/.local/lib/python3.8/site-packages/***/settings.py:195 DeprecationWarning: The sql_alchemy_conn option in [core] has been moved to the sql_alchemy_conn option in [database] - the old setting has been used, but please update your config.
[2024-04-06T23:01:05.284+0000] {task_command.py:423} INFO - Running <TaskInstance: defi_data_pipeline.transform_to_add_datetime scheduled__2024-04-06T22:01:00+00:00 [running]> on host aa86d21a7ebc
[2024-04-06T23:01:05.411+0000] {taskinstance.py:2481} INFO - Exporting env vars: AIRFLOW_CTX_DAG_OWNER='***' AIRFLOW_CTX_DAG_ID='defi_data_pipeline' AIRFLOW_CTX_TASK_ID='transform_to_add_datetime' AIRFLOW_CTX_EXECUTION_DATE='2024-04-06T22:01:00+00:00' AIRFLOW_CTX_TRY_NUMBER='1' AIRFLOW_CTX_DAG_RUN_ID='scheduled__2024-04-06T22:01:00+00:00'
[2024-04-06T23:01:05.428+0000] {taskinstance.py:2699} ERROR - Task failed with exception
Traceback (most recent call last):
  File "/home/airflow/.local/lib/python3.8/site-packages/airflow/models/taskinstance.py", line 433, in _execute_task
    result = execute_callable(context=context, **execute_callable_kwargs)
  File "/home/airflow/.local/lib/python3.8/site-packages/airflow/decorators/base.py", line 242, in execute
    return_value = super().execute(context)
  File "/home/airflow/.local/lib/python3.8/site-packages/airflow/operators/python.py", line 199, in execute
    return_value = self.execute_callable()
  File "/home/airflow/.local/lib/python3.8/site-packages/airflow/operators/python.py", line 216, in execute_callable
    return self.python_callable(*self.op_args, **self.op_kwargs)
  File "/opt/airflow/dags/_etl.py", line 70, in transform_to_add_datetime
    df['updated_dt'] = df['updated_dt'].apply(
  File "/home/airflow/.local/lib/python3.8/site-packages/pandas/core/series.py", line 4630, in apply
    return SeriesApply(self, func, convert_dtype, args, kwargs).apply()
  File "/home/airflow/.local/lib/python3.8/site-packages/pandas/core/apply.py", line 1025, in apply
    return self.apply_standard()
  File "/home/airflow/.local/lib/python3.8/site-packages/pandas/core/apply.py", line 1076, in apply_standard
    mapped = lib.map_infer(
  File "pandas/_libs/lib.pyx", line 2834, in pandas._libs.lib.map_infer
  File "/opt/airflow/dags/_etl.py", line 71, in <lambda>
    lambda x: str(x.replace(tzinfo=None))
AttributeError: 'PlainXComArg' object has no attribute 'replace'
[2024-04-06T23:01:05.445+0000] {taskinstance.py:1138} INFO - Marking task as FAILED. dag_id=defi_data_pipeline, task_id=transform_to_add_datetime, execution_date=20240406T220100, start_date=20240406T230104, end_date=20240406T230105
[2024-04-06T23:01:05.466+0000] {standard_task_runner.py:107} ERROR - Failed to execute job 321 for task transform_to_add_datetime ('PlainXComArg' object has no attribute 'replace'; 13075)
[2024-04-06T23:01:05.502+0000] {local_task_job_runner.py:234} INFO - Task exited with return code 1
[2024-04-06T23:01:05.531+0000] {taskinstance.py:3281} INFO - 0 downstream tasks scheduled from follow-on schedule check
[2024-04-06T23:07:14.416+0000] {taskinstance.py:1957} INFO - Dependencies all met for dep_context=non-requeueable deps ti=<TaskInstance: defi_data_pipeline.transform_to_add_datetime scheduled__2024-04-06T22:01:00+00:00 [queued]>
[2024-04-06T23:07:14.440+0000] {taskinstance.py:1957} INFO - Dependencies all met for dep_context=requeueable deps ti=<TaskInstance: defi_data_pipeline.transform_to_add_datetime scheduled__2024-04-06T22:01:00+00:00 [queued]>
[2024-04-06T23:07:14.442+0000] {taskinstance.py:2171} INFO - Starting attempt 1 of 1
[2024-04-06T23:07:14.845+0000] {taskinstance.py:2192} INFO - Executing <Task(_PythonDecoratedOperator): transform_to_add_datetime> on 2024-04-06 22:01:00+00:00
[2024-04-06T23:07:14.859+0000] {standard_task_runner.py:60} INFO - Started process 13467 to run task
[2024-04-06T23:07:14.865+0000] {standard_task_runner.py:87} INFO - Running: ['***', 'tasks', 'run', 'defi_data_pipeline', 'transform_to_add_datetime', 'scheduled__2024-04-06T22:01:00+00:00', '--job-id', '325', '--raw', '--subdir', 'DAGS_FOLDER/_etl.py', '--cfg-path', '/tmp/tmpuqbxbmyp']
[2024-04-06T23:07:14.874+0000] {standard_task_runner.py:88} INFO - Job 325: Subtask transform_to_add_datetime
[2024-04-06T23:07:14.907+0000] {logging_mixin.py:188} WARNING - /home/***/.local/lib/python3.8/site-packages/***/settings.py:195 DeprecationWarning: The sql_alchemy_conn option in [core] has been moved to the sql_alchemy_conn option in [database] - the old setting has been used, but please update your config.
[2024-04-06T23:07:14.999+0000] {task_command.py:423} INFO - Running <TaskInstance: defi_data_pipeline.transform_to_add_datetime scheduled__2024-04-06T22:01:00+00:00 [running]> on host aa86d21a7ebc
[2024-04-06T23:07:15.401+0000] {taskinstance.py:2481} INFO - Exporting env vars: AIRFLOW_CTX_DAG_OWNER='***' AIRFLOW_CTX_DAG_ID='defi_data_pipeline' AIRFLOW_CTX_TASK_ID='transform_to_add_datetime' AIRFLOW_CTX_EXECUTION_DATE='2024-04-06T22:01:00+00:00' AIRFLOW_CTX_TRY_NUMBER='1' AIRFLOW_CTX_DAG_RUN_ID='scheduled__2024-04-06T22:01:00+00:00'
[2024-04-06T23:07:15.511+0000] {taskinstance.py:2699} ERROR - Task failed with exception
Traceback (most recent call last):
  File "/home/airflow/.local/lib/python3.8/site-packages/airflow/models/taskinstance.py", line 433, in _execute_task
    result = execute_callable(context=context, **execute_callable_kwargs)
  File "/home/airflow/.local/lib/python3.8/site-packages/airflow/decorators/base.py", line 242, in execute
    return_value = super().execute(context)
  File "/home/airflow/.local/lib/python3.8/site-packages/airflow/operators/python.py", line 199, in execute
    return_value = self.execute_callable()
  File "/home/airflow/.local/lib/python3.8/site-packages/airflow/operators/python.py", line 216, in execute_callable
    return self.python_callable(*self.op_args, **self.op_kwargs)
  File "/opt/airflow/dags/_etl.py", line 72, in transform_to_add_datetime
    df['updated_dt'] = df['updated_dt'].apply(
  File "/home/airflow/.local/lib/python3.8/site-packages/pandas/core/series.py", line 4630, in apply
    return SeriesApply(self, func, convert_dtype, args, kwargs).apply()
  File "/home/airflow/.local/lib/python3.8/site-packages/pandas/core/apply.py", line 1025, in apply
    return self.apply_standard()
  File "/home/airflow/.local/lib/python3.8/site-packages/pandas/core/apply.py", line 1076, in apply_standard
    mapped = lib.map_infer(
  File "pandas/_libs/lib.pyx", line 2834, in pandas._libs.lib.map_infer
  File "/opt/airflow/dags/_etl.py", line 73, in <lambda>
    lambda x: str(x.replace(tzinfo=None))
AttributeError: 'PlainXComArg' object has no attribute 'replace'
[2024-04-06T23:07:15.557+0000] {taskinstance.py:1138} INFO - Marking task as FAILED. dag_id=defi_data_pipeline, task_id=transform_to_add_datetime, execution_date=20240406T220100, start_date=20240406T230714, end_date=20240406T230715
[2024-04-06T23:07:15.677+0000] {standard_task_runner.py:107} ERROR - Failed to execute job 325 for task transform_to_add_datetime ('PlainXComArg' object has no attribute 'replace'; 13467)
[2024-04-06T23:07:15.767+0000] {local_task_job_runner.py:234} INFO - Task exited with return code 1
[2024-04-06T23:07:15.859+0000] {taskinstance.py:3281} INFO - 0 downstream tasks scheduled from follow-on schedule check
[2024-04-06T23:11:55.082+0000] {taskinstance.py:1957} INFO - Dependencies all met for dep_context=non-requeueable deps ti=<TaskInstance: defi_data_pipeline.transform_to_add_datetime scheduled__2024-04-06T22:01:00+00:00 [queued]>
[2024-04-06T23:11:55.106+0000] {taskinstance.py:1957} INFO - Dependencies all met for dep_context=requeueable deps ti=<TaskInstance: defi_data_pipeline.transform_to_add_datetime scheduled__2024-04-06T22:01:00+00:00 [queued]>
[2024-04-06T23:11:55.107+0000] {taskinstance.py:2171} INFO - Starting attempt 1 of 1
[2024-04-06T23:11:55.775+0000] {taskinstance.py:2192} INFO - Executing <Task(_PythonDecoratedOperator): transform_to_add_datetime> on 2024-04-06 22:01:00+00:00
[2024-04-06T23:11:55.831+0000] {standard_task_runner.py:60} INFO - Started process 13770 to run task
[2024-04-06T23:11:55.858+0000] {standard_task_runner.py:87} INFO - Running: ['***', 'tasks', 'run', 'defi_data_pipeline', 'transform_to_add_datetime', 'scheduled__2024-04-06T22:01:00+00:00', '--job-id', '331', '--raw', '--subdir', 'DAGS_FOLDER/_etl.py', '--cfg-path', '/tmp/tmpql81fkf6']
[2024-04-06T23:11:55.863+0000] {standard_task_runner.py:88} INFO - Job 331: Subtask transform_to_add_datetime
[2024-04-06T23:11:55.971+0000] {logging_mixin.py:188} WARNING - /home/***/.local/lib/python3.8/site-packages/***/settings.py:195 DeprecationWarning: The sql_alchemy_conn option in [core] has been moved to the sql_alchemy_conn option in [database] - the old setting has been used, but please update your config.
[2024-04-06T23:11:56.171+0000] {task_command.py:423} INFO - Running <TaskInstance: defi_data_pipeline.transform_to_add_datetime scheduled__2024-04-06T22:01:00+00:00 [running]> on host aa86d21a7ebc
[2024-04-06T23:11:56.931+0000] {taskinstance.py:2481} INFO - Exporting env vars: AIRFLOW_CTX_DAG_OWNER='***' AIRFLOW_CTX_DAG_ID='defi_data_pipeline' AIRFLOW_CTX_TASK_ID='transform_to_add_datetime' AIRFLOW_CTX_EXECUTION_DATE='2024-04-06T22:01:00+00:00' AIRFLOW_CTX_TRY_NUMBER='1' AIRFLOW_CTX_DAG_RUN_ID='scheduled__2024-04-06T22:01:00+00:00'
[2024-04-06T23:11:56.971+0000] {python.py:201} INFO - Done. Returned value was:   token_name  ...                                         updated_dt
0    bitcoin  ...  {{ task_instance.xcom_pull(task_ids='get_utc_f...
1   ethereum  ...  {{ task_instance.xcom_pull(task_ids='get_utc_f...
2   marscoin  ...  {{ task_instance.xcom_pull(task_ids='get_utc_f...
3     solana  ...  {{ task_instance.xcom_pull(task_ids='get_utc_f...

[4 rows x 7 columns]
[2024-04-06T23:11:57.089+0000] {xcom.py:664} ERROR - ('Could not convert XComArg(<Task(_PythonDecoratedOperator): get_utc_from_unix_time>) with type PlainXComArg: did not recognize Python value type when inferring an Arrow data type', 'Conversion failed for column updated_dt with type object'). If you are using pickle instead of JSON for XCom, then you need to enable pickle support for XCom in your *** config or make sure to decorate your object with attr.
[2024-04-06T23:11:57.091+0000] {taskinstance.py:2699} ERROR - Task failed with exception
Traceback (most recent call last):
  File "/home/airflow/.local/lib/python3.8/site-packages/airflow/models/taskinstance.py", line 440, in _execute_task
    task_instance.xcom_push(key=XCOM_RETURN_KEY, value=xcom_value, session=session)
  File "/home/airflow/.local/lib/python3.8/site-packages/airflow/utils/session.py", line 76, in wrapper
    return func(*args, **kwargs)
  File "/home/airflow/.local/lib/python3.8/site-packages/airflow/models/taskinstance.py", line 2981, in xcom_push
    XCom.set(
  File "/home/airflow/.local/lib/python3.8/site-packages/airflow/utils/session.py", line 76, in wrapper
    return func(*args, **kwargs)
  File "/home/airflow/.local/lib/python3.8/site-packages/airflow/models/xcom.py", line 247, in set
    value = cls.serialize_value(
  File "/home/airflow/.local/lib/python3.8/site-packages/airflow/models/xcom.py", line 662, in serialize_value
    return json.dumps(value, cls=XComEncoder).encode("UTF-8")
  File "/usr/local/lib/python3.8/json/__init__.py", line 234, in dumps
    return cls(
  File "/home/airflow/.local/lib/python3.8/site-packages/airflow/utils/json.py", line 104, in encode
    return super().encode(o)
  File "/usr/local/lib/python3.8/json/encoder.py", line 199, in encode
    chunks = self.iterencode(o, _one_shot=True)
  File "/usr/local/lib/python3.8/json/encoder.py", line 257, in iterencode
    return _iterencode(o, 0)
  File "/home/airflow/.local/lib/python3.8/site-packages/airflow/utils/json.py", line 91, in default
    return serialize(o)
  File "/home/airflow/.local/lib/python3.8/site-packages/airflow/serialization/serde.py", line 145, in serialize
    data, classname, version, is_serialized = _serializers[qn].serialize(o)
  File "/home/airflow/.local/lib/python3.8/site-packages/airflow/serialization/serializers/pandas.py", line 49, in serialize
    table = pa.Table.from_pandas(o)
  File "pyarrow/table.pxi", line 3557, in pyarrow.lib.Table.from_pandas
  File "/home/airflow/.local/lib/python3.8/site-packages/pyarrow/pandas_compat.py", line 611, in dataframe_to_arrays
    arrays = [convert_column(c, f)
  File "/home/airflow/.local/lib/python3.8/site-packages/pyarrow/pandas_compat.py", line 611, in <listcomp>
    arrays = [convert_column(c, f)
  File "/home/airflow/.local/lib/python3.8/site-packages/pyarrow/pandas_compat.py", line 598, in convert_column
    raise e
  File "/home/airflow/.local/lib/python3.8/site-packages/pyarrow/pandas_compat.py", line 592, in convert_column
    result = pa.array(col, type=type_, from_pandas=True, safe=safe)
  File "pyarrow/array.pxi", line 316, in pyarrow.lib.array
  File "pyarrow/array.pxi", line 83, in pyarrow.lib._ndarray_to_array
  File "pyarrow/error.pxi", line 100, in pyarrow.lib.check_status
pyarrow.lib.ArrowInvalid: ('Could not convert XComArg(<Task(_PythonDecoratedOperator): get_utc_from_unix_time>) with type PlainXComArg: did not recognize Python value type when inferring an Arrow data type', 'Conversion failed for column updated_dt with type object')
[2024-04-06T23:11:57.108+0000] {taskinstance.py:1138} INFO - Marking task as FAILED. dag_id=defi_data_pipeline, task_id=transform_to_add_datetime, execution_date=20240406T220100, start_date=20240406T231155, end_date=20240406T231157
[2024-04-06T23:11:57.131+0000] {standard_task_runner.py:107} ERROR - Failed to execute job 331 for task transform_to_add_datetime (('Could not convert XComArg(<Task(_PythonDecoratedOperator): get_utc_from_unix_time>) with type PlainXComArg: did not recognize Python value type when inferring an Arrow data type', 'Conversion failed for column updated_dt with type object'); 13770)
[2024-04-06T23:11:57.152+0000] {local_task_job_runner.py:234} INFO - Task exited with return code 1
[2024-04-06T23:11:57.188+0000] {taskinstance.py:3281} INFO - 0 downstream tasks scheduled from follow-on schedule check
[2024-04-06T23:24:51.915+0000] {taskinstance.py:1957} INFO - Dependencies all met for dep_context=non-requeueable deps ti=<TaskInstance: defi_data_pipeline.transform_to_add_datetime scheduled__2024-04-06T22:01:00+00:00 [queued]>
[2024-04-06T23:24:51.954+0000] {taskinstance.py:1957} INFO - Dependencies all met for dep_context=requeueable deps ti=<TaskInstance: defi_data_pipeline.transform_to_add_datetime scheduled__2024-04-06T22:01:00+00:00 [queued]>
[2024-04-06T23:24:51.955+0000] {taskinstance.py:2171} INFO - Starting attempt 1 of 1
[2024-04-06T23:24:52.344+0000] {taskinstance.py:2192} INFO - Executing <Task(_PythonDecoratedOperator): transform_to_add_datetime> on 2024-04-06 22:01:00+00:00
[2024-04-06T23:24:52.352+0000] {standard_task_runner.py:60} INFO - Started process 14554 to run task
[2024-04-06T23:24:52.359+0000] {standard_task_runner.py:87} INFO - Running: ['***', 'tasks', 'run', 'defi_data_pipeline', 'transform_to_add_datetime', 'scheduled__2024-04-06T22:01:00+00:00', '--job-id', '333', '--raw', '--subdir', 'DAGS_FOLDER/_etl.py', '--cfg-path', '/tmp/tmpo9p5w2le']
[2024-04-06T23:24:52.364+0000] {standard_task_runner.py:88} INFO - Job 333: Subtask transform_to_add_datetime
[2024-04-06T23:24:52.397+0000] {logging_mixin.py:188} WARNING - /home/***/.local/lib/python3.8/site-packages/***/settings.py:195 DeprecationWarning: The sql_alchemy_conn option in [core] has been moved to the sql_alchemy_conn option in [database] - the old setting has been used, but please update your config.
[2024-04-06T23:24:52.463+0000] {task_command.py:423} INFO - Running <TaskInstance: defi_data_pipeline.transform_to_add_datetime scheduled__2024-04-06T22:01:00+00:00 [running]> on host aa86d21a7ebc
[2024-04-06T23:24:52.714+0000] {taskinstance.py:2481} INFO - Exporting env vars: AIRFLOW_CTX_DAG_OWNER='***' AIRFLOW_CTX_DAG_ID='defi_data_pipeline' AIRFLOW_CTX_TASK_ID='transform_to_add_datetime' AIRFLOW_CTX_EXECUTION_DATE='2024-04-06T22:01:00+00:00' AIRFLOW_CTX_TRY_NUMBER='1' AIRFLOW_CTX_DAG_RUN_ID='scheduled__2024-04-06T22:01:00+00:00'
[2024-04-06T23:24:52.737+0000] {python.py:201} INFO - Done. Returned value was:   token_name  ...                                         updated_dt
0    bitcoin  ...  {{ task_instance.xcom_pull(task_ids='get_utc_f...
1   ethereum  ...  {{ task_instance.xcom_pull(task_ids='get_utc_f...
2   marscoin  ...  {{ task_instance.xcom_pull(task_ids='get_utc_f...
3     solana  ...  {{ task_instance.xcom_pull(task_ids='get_utc_f...

[4 rows x 7 columns]
[2024-04-06T23:24:52.810+0000] {xcom.py:664} ERROR - ('Could not convert XComArg(<Task(_PythonDecoratedOperator): get_utc_from_unix_time>) with type PlainXComArg: did not recognize Python value type when inferring an Arrow data type', 'Conversion failed for column updated_dt with type object'). If you are using pickle instead of JSON for XCom, then you need to enable pickle support for XCom in your *** config or make sure to decorate your object with attr.
[2024-04-06T23:24:52.812+0000] {taskinstance.py:2699} ERROR - Task failed with exception
Traceback (most recent call last):
  File "/home/airflow/.local/lib/python3.8/site-packages/airflow/models/taskinstance.py", line 440, in _execute_task
    task_instance.xcom_push(key=XCOM_RETURN_KEY, value=xcom_value, session=session)
  File "/home/airflow/.local/lib/python3.8/site-packages/airflow/utils/session.py", line 76, in wrapper
    return func(*args, **kwargs)
  File "/home/airflow/.local/lib/python3.8/site-packages/airflow/models/taskinstance.py", line 2981, in xcom_push
    XCom.set(
  File "/home/airflow/.local/lib/python3.8/site-packages/airflow/utils/session.py", line 76, in wrapper
    return func(*args, **kwargs)
  File "/home/airflow/.local/lib/python3.8/site-packages/airflow/models/xcom.py", line 247, in set
    value = cls.serialize_value(
  File "/home/airflow/.local/lib/python3.8/site-packages/airflow/models/xcom.py", line 662, in serialize_value
    return json.dumps(value, cls=XComEncoder).encode("UTF-8")
  File "/usr/local/lib/python3.8/json/__init__.py", line 234, in dumps
    return cls(
  File "/home/airflow/.local/lib/python3.8/site-packages/airflow/utils/json.py", line 104, in encode
    return super().encode(o)
  File "/usr/local/lib/python3.8/json/encoder.py", line 199, in encode
    chunks = self.iterencode(o, _one_shot=True)
  File "/usr/local/lib/python3.8/json/encoder.py", line 257, in iterencode
    return _iterencode(o, 0)
  File "/home/airflow/.local/lib/python3.8/site-packages/airflow/utils/json.py", line 91, in default
    return serialize(o)
  File "/home/airflow/.local/lib/python3.8/site-packages/airflow/serialization/serde.py", line 145, in serialize
    data, classname, version, is_serialized = _serializers[qn].serialize(o)
  File "/home/airflow/.local/lib/python3.8/site-packages/airflow/serialization/serializers/pandas.py", line 49, in serialize
    table = pa.Table.from_pandas(o)
  File "pyarrow/table.pxi", line 3557, in pyarrow.lib.Table.from_pandas
  File "/home/airflow/.local/lib/python3.8/site-packages/pyarrow/pandas_compat.py", line 611, in dataframe_to_arrays
    arrays = [convert_column(c, f)
  File "/home/airflow/.local/lib/python3.8/site-packages/pyarrow/pandas_compat.py", line 611, in <listcomp>
    arrays = [convert_column(c, f)
  File "/home/airflow/.local/lib/python3.8/site-packages/pyarrow/pandas_compat.py", line 598, in convert_column
    raise e
  File "/home/airflow/.local/lib/python3.8/site-packages/pyarrow/pandas_compat.py", line 592, in convert_column
    result = pa.array(col, type=type_, from_pandas=True, safe=safe)
  File "pyarrow/array.pxi", line 316, in pyarrow.lib.array
  File "pyarrow/array.pxi", line 83, in pyarrow.lib._ndarray_to_array
  File "pyarrow/error.pxi", line 100, in pyarrow.lib.check_status
pyarrow.lib.ArrowInvalid: ('Could not convert XComArg(<Task(_PythonDecoratedOperator): get_utc_from_unix_time>) with type PlainXComArg: did not recognize Python value type when inferring an Arrow data type', 'Conversion failed for column updated_dt with type object')
[2024-04-06T23:24:52.825+0000] {taskinstance.py:1138} INFO - Marking task as FAILED. dag_id=defi_data_pipeline, task_id=transform_to_add_datetime, execution_date=20240406T220100, start_date=20240406T232451, end_date=20240406T232452
[2024-04-06T23:24:52.847+0000] {standard_task_runner.py:107} ERROR - Failed to execute job 333 for task transform_to_add_datetime (('Could not convert XComArg(<Task(_PythonDecoratedOperator): get_utc_from_unix_time>) with type PlainXComArg: did not recognize Python value type when inferring an Arrow data type', 'Conversion failed for column updated_dt with type object'); 14554)
[2024-04-06T23:24:52.896+0000] {local_task_job_runner.py:234} INFO - Task exited with return code 1
[2024-04-06T23:24:52.928+0000] {taskinstance.py:3281} INFO - 0 downstream tasks scheduled from follow-on schedule check
[2024-04-06T23:42:37.662+0000] {taskinstance.py:1957} INFO - Dependencies all met for dep_context=non-requeueable deps ti=<TaskInstance: defi_data_pipeline.transform_to_add_datetime scheduled__2024-04-06T22:01:00+00:00 [queued]>
[2024-04-06T23:42:37.705+0000] {taskinstance.py:1957} INFO - Dependencies all met for dep_context=requeueable deps ti=<TaskInstance: defi_data_pipeline.transform_to_add_datetime scheduled__2024-04-06T22:01:00+00:00 [queued]>
[2024-04-06T23:42:37.706+0000] {taskinstance.py:2171} INFO - Starting attempt 1 of 1
[2024-04-06T23:42:38.037+0000] {taskinstance.py:2192} INFO - Executing <Task(_PythonDecoratedOperator): transform_to_add_datetime> on 2024-04-06 22:01:00+00:00
[2024-04-06T23:42:38.047+0000] {standard_task_runner.py:60} INFO - Started process 15640 to run task
[2024-04-06T23:42:38.053+0000] {standard_task_runner.py:87} INFO - Running: ['***', 'tasks', 'run', 'defi_data_pipeline', 'transform_to_add_datetime', 'scheduled__2024-04-06T22:01:00+00:00', '--job-id', '335', '--raw', '--subdir', 'DAGS_FOLDER/_etl.py', '--cfg-path', '/tmp/tmp9i3ay9u3']
[2024-04-06T23:42:38.059+0000] {standard_task_runner.py:88} INFO - Job 335: Subtask transform_to_add_datetime
[2024-04-06T23:42:38.092+0000] {logging_mixin.py:188} WARNING - /home/***/.local/lib/python3.8/site-packages/***/settings.py:195 DeprecationWarning: The sql_alchemy_conn option in [core] has been moved to the sql_alchemy_conn option in [database] - the old setting has been used, but please update your config.
[2024-04-06T23:42:38.209+0000] {task_command.py:423} INFO - Running <TaskInstance: defi_data_pipeline.transform_to_add_datetime scheduled__2024-04-06T22:01:00+00:00 [running]> on host aa86d21a7ebc
[2024-04-06T23:42:38.546+0000] {taskinstance.py:2481} INFO - Exporting env vars: AIRFLOW_CTX_DAG_OWNER='***' AIRFLOW_CTX_DAG_ID='defi_data_pipeline' AIRFLOW_CTX_TASK_ID='transform_to_add_datetime' AIRFLOW_CTX_EXECUTION_DATE='2024-04-06T22:01:00+00:00' AIRFLOW_CTX_TRY_NUMBER='1' AIRFLOW_CTX_DAG_RUN_ID='scheduled__2024-04-06T22:01:00+00:00'
[2024-04-06T23:42:38.582+0000] {python.py:201} INFO - Done. Returned value was:   token_name          usd  ...  last_updated_at           updated_dt
0    bitcoin  69196.98186  ...     1.712447e+09  2024-04-06 23:42:30
1   ethereum   3371.90199  ...     1.712447e+09  2024-04-06 23:41:52
2   marscoin      0.09933  ...     1.712447e+09  2024-04-06 23:42:21
3     solana    179.12374  ...     1.712447e+09  2024-04-06 23:42:07

[4 rows x 7 columns]
[2024-04-06T23:42:38.770+0000] {taskinstance.py:1138} INFO - Marking task as SUCCESS. dag_id=defi_data_pipeline, task_id=transform_to_add_datetime, execution_date=20240406T220100, start_date=20240406T234237, end_date=20240406T234238
[2024-04-06T23:42:38.824+0000] {local_task_job_runner.py:234} INFO - Task exited with return code 0
[2024-04-06T23:42:38.865+0000] {taskinstance.py:3281} INFO - 0 downstream tasks scheduled from follow-on schedule check
