[2024-04-06T23:11:11.795+0000] {taskinstance.py:1957} INFO - Dependencies all met for dep_context=non-requeueable deps ti=<TaskInstance: defi_data_pipeline.transform_to_add_datetime scheduled__2024-04-06T22:01:00+00:00 [queued]>
[2024-04-06T23:11:11.827+0000] {taskinstance.py:1957} INFO - Dependencies all met for dep_context=requeueable deps ti=<TaskInstance: defi_data_pipeline.transform_to_add_datetime scheduled__2024-04-06T22:01:00+00:00 [queued]>
[2024-04-06T23:11:11.829+0000] {taskinstance.py:2171} INFO - Starting attempt 3 of 3
[2024-04-06T23:11:12.093+0000] {taskinstance.py:2192} INFO - Executing <Task(_PythonDecoratedOperator): transform_to_add_datetime> on 2024-04-06 22:01:00+00:00
[2024-04-06T23:11:12.102+0000] {standard_task_runner.py:60} INFO - Started process 13717 to run task
[2024-04-06T23:11:12.107+0000] {standard_task_runner.py:87} INFO - Running: ['***', 'tasks', 'run', 'defi_data_pipeline', 'transform_to_add_datetime', 'scheduled__2024-04-06T22:01:00+00:00', '--job-id', '329', '--raw', '--subdir', 'DAGS_FOLDER/_etl.py', '--cfg-path', '/tmp/tmpfzn44hiz']
[2024-04-06T23:11:12.113+0000] {standard_task_runner.py:88} INFO - Job 329: Subtask transform_to_add_datetime
[2024-04-06T23:11:12.139+0000] {logging_mixin.py:188} WARNING - /home/***/.local/lib/python3.8/site-packages/***/settings.py:195 DeprecationWarning: The sql_alchemy_conn option in [core] has been moved to the sql_alchemy_conn option in [database] - the old setting has been used, but please update your config.
[2024-04-06T23:11:12.211+0000] {task_command.py:423} INFO - Running <TaskInstance: defi_data_pipeline.transform_to_add_datetime scheduled__2024-04-06T22:01:00+00:00 [running]> on host aa86d21a7ebc
[2024-04-06T23:11:12.472+0000] {taskinstance.py:2481} INFO - Exporting env vars: AIRFLOW_CTX_DAG_OWNER='***' AIRFLOW_CTX_DAG_ID='defi_data_pipeline' AIRFLOW_CTX_TASK_ID='transform_to_add_datetime' AIRFLOW_CTX_EXECUTION_DATE='2024-04-06T22:01:00+00:00' AIRFLOW_CTX_TRY_NUMBER='3' AIRFLOW_CTX_DAG_RUN_ID='scheduled__2024-04-06T22:01:00+00:00'
[2024-04-06T23:11:12.510+0000] {python.py:201} INFO - Done. Returned value was:   token_name  ...                                         updated_dt
0    bitcoin  ...  {{ task_instance.xcom_pull(task_ids='get_utc_f...
1   ethereum  ...  {{ task_instance.xcom_pull(task_ids='get_utc_f...
2   marscoin  ...  {{ task_instance.xcom_pull(task_ids='get_utc_f...
3     solana  ...  {{ task_instance.xcom_pull(task_ids='get_utc_f...

[4 rows x 7 columns]
[2024-04-06T23:11:12.586+0000] {xcom.py:664} ERROR - ('Could not convert XComArg(<Task(_PythonDecoratedOperator): get_utc_from_unix_time>) with type PlainXComArg: did not recognize Python value type when inferring an Arrow data type', 'Conversion failed for column updated_dt with type object'). If you are using pickle instead of JSON for XCom, then you need to enable pickle support for XCom in your *** config or make sure to decorate your object with attr.
[2024-04-06T23:11:12.589+0000] {taskinstance.py:2699} ERROR - Task failed with exception
Traceback (most recent call last):
  File "/home/airflow/.local/lib/python3.8/site-packages/airflow/models/taskinstance.py", line 440, in _execute_task
    task_instance.xcom_push(key=XCOM_RETURN_KEY, value=xcom_value, session=session)
  File "/home/airflow/.local/lib/python3.8/site-packages/airflow/utils/session.py", line 76, in wrapper
    return func(*args, **kwargs)
  File "/home/airflow/.local/lib/python3.8/site-packages/airflow/models/taskinstance.py", line 2981, in xcom_push
    XCom.set(
  File "/home/airflow/.local/lib/python3.8/site-packages/airflow/utils/session.py", line 76, in wrapper
    return func(*args, **kwargs)
  File "/home/airflow/.local/lib/python3.8/site-packages/airflow/models/xcom.py", line 247, in set
    value = cls.serialize_value(
  File "/home/airflow/.local/lib/python3.8/site-packages/airflow/models/xcom.py", line 662, in serialize_value
    return json.dumps(value, cls=XComEncoder).encode("UTF-8")
  File "/usr/local/lib/python3.8/json/__init__.py", line 234, in dumps
    return cls(
  File "/home/airflow/.local/lib/python3.8/site-packages/airflow/utils/json.py", line 104, in encode
    return super().encode(o)
  File "/usr/local/lib/python3.8/json/encoder.py", line 199, in encode
    chunks = self.iterencode(o, _one_shot=True)
  File "/usr/local/lib/python3.8/json/encoder.py", line 257, in iterencode
    return _iterencode(o, 0)
  File "/home/airflow/.local/lib/python3.8/site-packages/airflow/utils/json.py", line 91, in default
    return serialize(o)
  File "/home/airflow/.local/lib/python3.8/site-packages/airflow/serialization/serde.py", line 145, in serialize
    data, classname, version, is_serialized = _serializers[qn].serialize(o)
  File "/home/airflow/.local/lib/python3.8/site-packages/airflow/serialization/serializers/pandas.py", line 49, in serialize
    table = pa.Table.from_pandas(o)
  File "pyarrow/table.pxi", line 3557, in pyarrow.lib.Table.from_pandas
  File "/home/airflow/.local/lib/python3.8/site-packages/pyarrow/pandas_compat.py", line 611, in dataframe_to_arrays
    arrays = [convert_column(c, f)
  File "/home/airflow/.local/lib/python3.8/site-packages/pyarrow/pandas_compat.py", line 611, in <listcomp>
    arrays = [convert_column(c, f)
  File "/home/airflow/.local/lib/python3.8/site-packages/pyarrow/pandas_compat.py", line 598, in convert_column
    raise e
  File "/home/airflow/.local/lib/python3.8/site-packages/pyarrow/pandas_compat.py", line 592, in convert_column
    result = pa.array(col, type=type_, from_pandas=True, safe=safe)
  File "pyarrow/array.pxi", line 316, in pyarrow.lib.array
  File "pyarrow/array.pxi", line 83, in pyarrow.lib._ndarray_to_array
  File "pyarrow/error.pxi", line 100, in pyarrow.lib.check_status
pyarrow.lib.ArrowInvalid: ('Could not convert XComArg(<Task(_PythonDecoratedOperator): get_utc_from_unix_time>) with type PlainXComArg: did not recognize Python value type when inferring an Arrow data type', 'Conversion failed for column updated_dt with type object')
[2024-04-06T23:11:12.606+0000] {taskinstance.py:1138} INFO - Marking task as FAILED. dag_id=defi_data_pipeline, task_id=transform_to_add_datetime, execution_date=20240406T220100, start_date=20240406T231111, end_date=20240406T231112
[2024-04-06T23:11:12.631+0000] {standard_task_runner.py:107} ERROR - Failed to execute job 329 for task transform_to_add_datetime (('Could not convert XComArg(<Task(_PythonDecoratedOperator): get_utc_from_unix_time>) with type PlainXComArg: did not recognize Python value type when inferring an Arrow data type', 'Conversion failed for column updated_dt with type object'); 13717)
[2024-04-06T23:11:12.684+0000] {local_task_job_runner.py:234} INFO - Task exited with return code 1
[2024-04-06T23:11:12.714+0000] {taskinstance.py:3281} INFO - 0 downstream tasks scheduled from follow-on schedule check
