[2024-04-07T10:07:26.679+0000] {taskinstance.py:1957} INFO - Dependencies all met for dep_context=non-requeueable deps ti=<TaskInstance: defi_data_pipeline.establish_database_conn scheduled__2024-04-07T09:05:00+00:00 [queued]>
[2024-04-07T10:07:26.701+0000] {taskinstance.py:1957} INFO - Dependencies all met for dep_context=requeueable deps ti=<TaskInstance: defi_data_pipeline.establish_database_conn scheduled__2024-04-07T09:05:00+00:00 [queued]>
[2024-04-07T10:07:26.703+0000] {taskinstance.py:2171} INFO - Starting attempt 1 of 1
[2024-04-07T10:07:26.941+0000] {taskinstance.py:2192} INFO - Executing <Task(_PythonDecoratedOperator): establish_database_conn> on 2024-04-07 09:05:00+00:00
[2024-04-07T10:07:26.951+0000] {standard_task_runner.py:60} INFO - Started process 27563 to run task
[2024-04-07T10:07:26.960+0000] {standard_task_runner.py:87} INFO - Running: ['***', 'tasks', 'run', 'defi_data_pipeline', 'establish_database_conn', 'scheduled__2024-04-07T09:05:00+00:00', '--job-id', '357', '--raw', '--subdir', 'DAGS_FOLDER/_etl.py', '--cfg-path', '/tmp/tmp0u44cu2r']
[2024-04-07T10:07:26.968+0000] {standard_task_runner.py:88} INFO - Job 357: Subtask establish_database_conn
[2024-04-07T10:07:26.998+0000] {logging_mixin.py:188} WARNING - /home/***/.local/lib/python3.8/site-packages/***/settings.py:195 DeprecationWarning: The sql_alchemy_conn option in [core] has been moved to the sql_alchemy_conn option in [database] - the old setting has been used, but please update your config.
[2024-04-07T10:07:27.083+0000] {task_command.py:423} INFO - Running <TaskInstance: defi_data_pipeline.establish_database_conn scheduled__2024-04-07T09:05:00+00:00 [running]> on host aa86d21a7ebc
[2024-04-07T10:07:27.290+0000] {taskinstance.py:2481} INFO - Exporting env vars: AIRFLOW_CTX_DAG_OWNER='***' AIRFLOW_CTX_DAG_ID='defi_data_pipeline' AIRFLOW_CTX_TASK_ID='establish_database_conn' AIRFLOW_CTX_EXECUTION_DATE='2024-04-07T09:05:00+00:00' AIRFLOW_CTX_TRY_NUMBER='1' AIRFLOW_CTX_DAG_RUN_ID='scheduled__2024-04-07T09:05:00+00:00'
[2024-04-07T10:07:27.323+0000] {base.py:83} INFO - Using connection ID 'defi_connection' for task execution.
[2024-04-07T10:07:27.325+0000] {taskinstance.py:2699} ERROR - Task failed with exception
Traceback (most recent call last):
  File "/home/airflow/.local/lib/python3.8/site-packages/airflow/models/taskinstance.py", line 433, in _execute_task
    result = execute_callable(context=context, **execute_callable_kwargs)
  File "/home/airflow/.local/lib/python3.8/site-packages/airflow/decorators/base.py", line 242, in execute
    return_value = super().execute(context)
  File "/home/airflow/.local/lib/python3.8/site-packages/airflow/operators/python.py", line 199, in execute
    return_value = self.execute_callable()
  File "/home/airflow/.local/lib/python3.8/site-packages/airflow/operators/python.py", line 216, in execute_callable
    return self.python_callable(*self.op_args, **self.op_kwargs)
  File "/opt/airflow/dags/_etl.py", line 70, in establish_database_conn
    conn = hook.get_conn()
  File "/home/airflow/.local/lib/python3.8/site-packages/airflow/providers/postgres/hooks/postgres.py", line 158, in get_conn
    self.conn = psycopg2.connect(**conn_args)
  File "/home/airflow/.local/lib/python3.8/site-packages/psycopg2/__init__.py", line 122, in connect
    conn = _connect(dsn, connection_factory=connection_factory, **kwasync)
psycopg2.OperationalError: connection to server at "localhost" (127.0.0.1), port 5432 failed: Connection refused
	Is the server running on that host and accepting TCP/IP connections?
connection to server at "localhost" (::1), port 5432 failed: Cannot assign requested address
	Is the server running on that host and accepting TCP/IP connections?

[2024-04-07T10:07:27.344+0000] {taskinstance.py:1138} INFO - Marking task as FAILED. dag_id=defi_data_pipeline, task_id=establish_database_conn, execution_date=20240407T090500, start_date=20240407T100726, end_date=20240407T100727
[2024-04-07T10:07:27.369+0000] {standard_task_runner.py:107} ERROR - Failed to execute job 357 for task establish_database_conn (connection to server at "localhost" (127.0.0.1), port 5432 failed: Connection refused
	Is the server running on that host and accepting TCP/IP connections?
connection to server at "localhost" (::1), port 5432 failed: Cannot assign requested address
	Is the server running on that host and accepting TCP/IP connections?
; 27563)
[2024-04-07T10:07:27.396+0000] {local_task_job_runner.py:234} INFO - Task exited with return code 1
[2024-04-07T10:07:27.422+0000] {taskinstance.py:3281} INFO - 0 downstream tasks scheduled from follow-on schedule check
