[2024-04-07T12:29:52.671+0000] {taskinstance.py:1957} INFO - Dependencies all met for dep_context=non-requeueable deps ti=<TaskInstance: defi_data_pipeline.establish_database_conn manual__2024-04-07T12:24:57.031993+00:00 [queued]>
[2024-04-07T12:29:52.685+0000] {taskinstance.py:1957} INFO - Dependencies all met for dep_context=requeueable deps ti=<TaskInstance: defi_data_pipeline.establish_database_conn manual__2024-04-07T12:24:57.031993+00:00 [queued]>
[2024-04-07T12:29:52.685+0000] {taskinstance.py:2171} INFO - Starting attempt 2 of 2
[2024-04-07T12:29:52.937+0000] {taskinstance.py:2192} INFO - Executing <Task(_PythonDecoratedOperator): establish_database_conn> on 2024-04-07 12:24:57.031993+00:00
[2024-04-07T12:29:52.951+0000] {standard_task_runner.py:60} INFO - Started process 36567 to run task
[2024-04-07T12:29:52.959+0000] {standard_task_runner.py:87} INFO - Running: ['***', 'tasks', 'run', 'defi_data_pipeline', 'establish_database_conn', 'manual__2024-04-07T12:24:57.031993+00:00', '--job-id', '389', '--raw', '--subdir', 'DAGS_FOLDER/_etl.py', '--cfg-path', '/tmp/tmpdahd_f76']
[2024-04-07T12:29:52.963+0000] {standard_task_runner.py:88} INFO - Job 389: Subtask establish_database_conn
[2024-04-07T12:29:52.989+0000] {logging_mixin.py:188} WARNING - /home/***/.local/lib/python3.8/site-packages/***/settings.py:195 DeprecationWarning: The sql_alchemy_conn option in [core] has been moved to the sql_alchemy_conn option in [database] - the old setting has been used, but please update your config.
[2024-04-07T12:29:53.041+0000] {task_command.py:423} INFO - Running <TaskInstance: defi_data_pipeline.establish_database_conn manual__2024-04-07T12:24:57.031993+00:00 [running]> on host aa86d21a7ebc
[2024-04-07T12:29:53.428+0000] {taskinstance.py:2481} INFO - Exporting env vars: AIRFLOW_CTX_DAG_OWNER='***' AIRFLOW_CTX_DAG_ID='defi_data_pipeline' AIRFLOW_CTX_TASK_ID='establish_database_conn' AIRFLOW_CTX_EXECUTION_DATE='2024-04-07T12:24:57.031993+00:00' AIRFLOW_CTX_TRY_NUMBER='2' AIRFLOW_CTX_DAG_RUN_ID='manual__2024-04-07T12:24:57.031993+00:00'
[2024-04-07T12:29:53.487+0000] {base.py:83} INFO - Using connection ID 'defi_connection' for task execution.
[2024-04-07T12:29:53.505+0000] {taskinstance.py:2699} ERROR - Task failed with exception
Traceback (most recent call last):
  File "/home/airflow/.local/lib/python3.8/site-packages/airflow/models/taskinstance.py", line 433, in _execute_task
    result = execute_callable(context=context, **execute_callable_kwargs)
  File "/home/airflow/.local/lib/python3.8/site-packages/airflow/decorators/base.py", line 242, in execute
    return_value = super().execute(context)
  File "/home/airflow/.local/lib/python3.8/site-packages/airflow/operators/python.py", line 199, in execute
    return_value = self.execute_callable()
  File "/home/airflow/.local/lib/python3.8/site-packages/airflow/operators/python.py", line 216, in execute_callable
    return self.python_callable(*self.op_args, **self.op_kwargs)
  File "/opt/airflow/dags/_etl.py", line 82, in establish_database_conn
    cursor.execute(qry, (data_frame,))
psycopg2.ProgrammingError: can't adapt type 'DataFrame'
[2024-04-07T12:29:53.542+0000] {taskinstance.py:1138} INFO - Marking task as FAILED. dag_id=defi_data_pipeline, task_id=establish_database_conn, execution_date=20240407T122457, start_date=20240407T122952, end_date=20240407T122953
[2024-04-07T12:29:53.594+0000] {standard_task_runner.py:107} ERROR - Failed to execute job 389 for task establish_database_conn (can't adapt type 'DataFrame'; 36567)
[2024-04-07T12:29:53.660+0000] {local_task_job_runner.py:234} INFO - Task exited with return code 1
[2024-04-07T12:29:53.763+0000] {taskinstance.py:3281} INFO - 0 downstream tasks scheduled from follow-on schedule check
