[2024-04-06T22:33:16.223+0000] {taskinstance.py:1957} INFO - Dependencies all met for dep_context=non-requeueable deps ti=<TaskInstance: defi_data_pipeline.insert_data_query scheduled__2024-04-06T19:10:00+00:00 [queued]>
[2024-04-06T22:33:16.321+0000] {taskinstance.py:1957} INFO - Dependencies all met for dep_context=requeueable deps ti=<TaskInstance: defi_data_pipeline.insert_data_query scheduled__2024-04-06T19:10:00+00:00 [queued]>
[2024-04-06T22:33:16.322+0000] {taskinstance.py:2171} INFO - Starting attempt 1 of 1
[2024-04-06T22:33:17.338+0000] {taskinstance.py:2192} INFO - Executing <Task(PostgresOperator): insert_data_query> on 2024-04-06 19:10:00+00:00
[2024-04-06T22:33:17.355+0000] {standard_task_runner.py:60} INFO - Started process 11239 to run task
[2024-04-06T22:33:17.370+0000] {standard_task_runner.py:87} INFO - Running: ['***', 'tasks', 'run', 'defi_data_pipeline', 'insert_data_query', 'scheduled__2024-04-06T19:10:00+00:00', '--job-id', '317', '--raw', '--subdir', 'DAGS_FOLDER/_etl.py', '--cfg-path', '/tmp/tmppas79f5t']
[2024-04-06T22:33:17.387+0000] {standard_task_runner.py:88} INFO - Job 317: Subtask insert_data_query
[2024-04-06T22:33:17.556+0000] {logging_mixin.py:188} WARNING - /home/***/.local/lib/python3.8/site-packages/***/settings.py:195 DeprecationWarning: The sql_alchemy_conn option in [core] has been moved to the sql_alchemy_conn option in [database] - the old setting has been used, but please update your config.
[2024-04-06T22:33:18.492+0000] {task_command.py:423} INFO - Running <TaskInstance: defi_data_pipeline.insert_data_query scheduled__2024-04-06T19:10:00+00:00 [running]> on host aa86d21a7ebc
[2024-04-06T22:33:18.964+0000] {abstractoperator.py:708} ERROR - Exception rendering Jinja template for task 'insert_data_query', field 'sql'. Template: "INSERT INTO defi.token (\n    token_name, \n    usd, \n    usd_market_cap, \n    usd_24h_vol, \n    usd_24h_change,\n    last_updated_at,\n    updated_at\n)\nSELECT\n    token_name, \n    usd, \n    usd_market_cap, \n    usd_24h_vol, \n    usd_24h_change,\n    last_updated_at,\n    updated_at\nFROM '{{data_frame}}'"
Traceback (most recent call last):
  File "/home/airflow/.local/lib/python3.8/site-packages/airflow/models/abstractoperator.py", line 700, in _do_render_template_fields
    rendered_content = self.render_template(
  File "/home/airflow/.local/lib/python3.8/site-packages/airflow/template/templater.py", line 174, in render_template
    return self._render(template, context)
  File "/home/airflow/.local/lib/python3.8/site-packages/airflow/models/abstractoperator.py", line 654, in _render
    return super()._render(template, context, dag=dag)
  File "/home/airflow/.local/lib/python3.8/site-packages/airflow/template/templater.py", line 131, in _render
    return render_template_to_string(template, context)
  File "/home/airflow/.local/lib/python3.8/site-packages/airflow/utils/helpers.py", line 289, in render_template_to_string
    return render_template(template, cast(MutableMapping[str, Any], context), native=False)
  File "/home/airflow/.local/lib/python3.8/site-packages/airflow/utils/helpers.py", line 284, in render_template
    return "".join(nodes)
  File "<template>", line 13, in root
  File "/home/airflow/.local/lib/python3.8/site-packages/jinja2/runtime.py", line 852, in _fail_with_undefined_error
    raise self._undefined_exception(self._undefined_message)
jinja2.exceptions.UndefinedError: 'data_frame' is undefined
[2024-04-06T22:33:18.971+0000] {taskinstance.py:2699} ERROR - Task failed with exception
Traceback (most recent call last):
  File "/home/airflow/.local/lib/python3.8/site-packages/airflow/models/taskinstance.py", line 2335, in _run_raw_task
    self._execute_task_with_callbacks(context, test_mode, session=session)
  File "/home/airflow/.local/lib/python3.8/site-packages/airflow/models/taskinstance.py", line 2466, in _execute_task_with_callbacks
    task_orig = self.render_templates(context=context)
  File "/home/airflow/.local/lib/python3.8/site-packages/airflow/models/taskinstance.py", line 2878, in render_templates
    original_task.render_template_fields(context)
  File "/home/airflow/.local/lib/python3.8/site-packages/airflow/models/baseoperator.py", line 1248, in render_template_fields
    self._do_render_template_fields(self, self.template_fields, context, jinja_env, set())
  File "/home/airflow/.local/lib/python3.8/site-packages/airflow/utils/session.py", line 79, in wrapper
    return func(*args, session=session, **kwargs)
  File "/home/airflow/.local/lib/python3.8/site-packages/airflow/models/abstractoperator.py", line 700, in _do_render_template_fields
    rendered_content = self.render_template(
  File "/home/airflow/.local/lib/python3.8/site-packages/airflow/template/templater.py", line 174, in render_template
    return self._render(template, context)
  File "/home/airflow/.local/lib/python3.8/site-packages/airflow/models/abstractoperator.py", line 654, in _render
    return super()._render(template, context, dag=dag)
  File "/home/airflow/.local/lib/python3.8/site-packages/airflow/template/templater.py", line 131, in _render
    return render_template_to_string(template, context)
  File "/home/airflow/.local/lib/python3.8/site-packages/airflow/utils/helpers.py", line 289, in render_template_to_string
    return render_template(template, cast(MutableMapping[str, Any], context), native=False)
  File "/home/airflow/.local/lib/python3.8/site-packages/airflow/utils/helpers.py", line 284, in render_template
    return "".join(nodes)
  File "<template>", line 13, in root
  File "/home/airflow/.local/lib/python3.8/site-packages/jinja2/runtime.py", line 852, in _fail_with_undefined_error
    raise self._undefined_exception(self._undefined_message)
jinja2.exceptions.UndefinedError: 'data_frame' is undefined
[2024-04-06T22:33:19.070+0000] {taskinstance.py:1138} INFO - Marking task as FAILED. dag_id=defi_data_pipeline, task_id=insert_data_query, execution_date=20240406T191000, start_date=20240406T223316, end_date=20240406T223319
[2024-04-06T22:33:19.523+0000] {standard_task_runner.py:107} ERROR - Failed to execute job 317 for task insert_data_query ('data_frame' is undefined; 11239)
[2024-04-06T22:33:19.632+0000] {local_task_job_runner.py:234} INFO - Task exited with return code 1
[2024-04-06T22:33:19.749+0000] {taskinstance.py:3281} INFO - 0 downstream tasks scheduled from follow-on schedule check
