[2024-04-07T11:41:28.102+0000] {taskinstance.py:1957} INFO - Dependencies all met for dep_context=non-requeueable deps ti=<TaskInstance: defi_data_pipeline.transformed_to_datetime scheduled__2024-04-07T10:01:00+00:00 [queued]>
[2024-04-07T11:41:28.125+0000] {taskinstance.py:1957} INFO - Dependencies all met for dep_context=requeueable deps ti=<TaskInstance: defi_data_pipeline.transformed_to_datetime scheduled__2024-04-07T10:01:00+00:00 [queued]>
[2024-04-07T11:41:28.126+0000] {taskinstance.py:2171} INFO - Starting attempt 2 of 2
[2024-04-07T11:41:28.517+0000] {taskinstance.py:2192} INFO - Executing <Task(_PythonDecoratedOperator): transformed_to_datetime> on 2024-04-07 10:01:00+00:00
[2024-04-07T11:41:28.530+0000] {standard_task_runner.py:60} INFO - Started process 33434 to run task
[2024-04-07T11:41:28.536+0000] {standard_task_runner.py:87} INFO - Running: ['***', 'tasks', 'run', 'defi_data_pipeline', 'transformed_to_datetime', 'scheduled__2024-04-07T10:01:00+00:00', '--job-id', '370', '--raw', '--subdir', 'DAGS_FOLDER/_etl.py', '--cfg-path', '/tmp/tmp7o2hczdw']
[2024-04-07T11:41:28.540+0000] {standard_task_runner.py:88} INFO - Job 370: Subtask transformed_to_datetime
[2024-04-07T11:41:28.578+0000] {logging_mixin.py:188} WARNING - /home/***/.local/lib/python3.8/site-packages/***/settings.py:195 DeprecationWarning: The sql_alchemy_conn option in [core] has been moved to the sql_alchemy_conn option in [database] - the old setting has been used, but please update your config.
[2024-04-07T11:41:28.634+0000] {task_command.py:423} INFO - Running <TaskInstance: defi_data_pipeline.transformed_to_datetime scheduled__2024-04-07T10:01:00+00:00 [running]> on host aa86d21a7ebc
[2024-04-07T11:41:28.737+0000] {taskinstance.py:2481} INFO - Exporting env vars: AIRFLOW_CTX_DAG_OWNER='***' AIRFLOW_CTX_DAG_ID='defi_data_pipeline' AIRFLOW_CTX_TASK_ID='transformed_to_datetime' AIRFLOW_CTX_EXECUTION_DATE='2024-04-07T10:01:00+00:00' AIRFLOW_CTX_TRY_NUMBER='2' AIRFLOW_CTX_DAG_RUN_ID='scheduled__2024-04-07T10:01:00+00:00'
[2024-04-07T11:41:28.742+0000] {taskinstance.py:2699} ERROR - Task failed with exception
Traceback (most recent call last):
  File "/home/airflow/.local/lib/python3.8/site-packages/airflow/models/taskinstance.py", line 433, in _execute_task
    result = execute_callable(context=context, **execute_callable_kwargs)
  File "/home/airflow/.local/lib/python3.8/site-packages/airflow/decorators/base.py", line 242, in execute
    return_value = super().execute(context)
  File "/home/airflow/.local/lib/python3.8/site-packages/airflow/operators/python.py", line 199, in execute
    return_value = self.execute_callable()
  File "/home/airflow/.local/lib/python3.8/site-packages/airflow/operators/python.py", line 216, in execute_callable
    return self.python_callable(*self.op_args, **self.op_kwargs)
  File "/opt/airflow/dags/_etl.py", line 58, in transformed_to_datetime
    transformed_data = pd.DataFrame(api_data).T.reset_index()
  File "/home/airflow/.local/lib/python3.8/site-packages/pandas/core/frame.py", line 774, in __init__
    data = list(data)
  File "/home/airflow/.local/lib/python3.8/site-packages/airflow/models/xcom_arg.py", line 270, in __iter__
    raise TypeError("'XComArg' object is not iterable")
TypeError: 'XComArg' object is not iterable
[2024-04-07T11:41:28.755+0000] {taskinstance.py:1138} INFO - Marking task as FAILED. dag_id=defi_data_pipeline, task_id=transformed_to_datetime, execution_date=20240407T100100, start_date=20240407T114128, end_date=20240407T114128
[2024-04-07T11:41:28.775+0000] {standard_task_runner.py:107} ERROR - Failed to execute job 370 for task transformed_to_datetime ('XComArg' object is not iterable; 33434)
[2024-04-07T11:41:28.790+0000] {local_task_job_runner.py:234} INFO - Task exited with return code 1
[2024-04-07T11:41:28.813+0000] {taskinstance.py:3281} INFO - 0 downstream tasks scheduled from follow-on schedule check
