[2024-04-07T11:26:30.170+0000] {scheduler_job_runner.py:781} ERROR - Executor reports task instance <TaskInstance: defi_data_pipeline.transformed_to_datetime scheduled__2024-04-07T10:01:00+00:00 [queued]> finished (failed) although the task says it's queued. (Info: None) Was the task killed externally?
