[2024-04-07T11:01:01.876+0000] {taskinstance.py:1957} INFO - Dependencies all met for dep_context=non-requeueable deps ti=<TaskInstance: defi_data_pipeline.establish_database_conn scheduled__2024-04-07T10:01:00+00:00 [queued]>
[2024-04-07T11:01:01.895+0000] {taskinstance.py:1957} INFO - Dependencies all met for dep_context=requeueable deps ti=<TaskInstance: defi_data_pipeline.establish_database_conn scheduled__2024-04-07T10:01:00+00:00 [queued]>
[2024-04-07T11:01:01.896+0000] {taskinstance.py:2171} INFO - Starting attempt 1 of 1
[2024-04-07T11:01:02.228+0000] {taskinstance.py:2192} INFO - Executing <Task(_PythonDecoratedOperator): establish_database_conn> on 2024-04-07 10:01:00+00:00
[2024-04-07T11:01:02.238+0000] {standard_task_runner.py:60} INFO - Started process 30854 to run task
[2024-04-07T11:01:02.245+0000] {standard_task_runner.py:87} INFO - Running: ['***', 'tasks', 'run', 'defi_data_pipeline', 'establish_database_conn', 'scheduled__2024-04-07T10:01:00+00:00', '--job-id', '362', '--raw', '--subdir', 'DAGS_FOLDER/_etl.py', '--cfg-path', '/tmp/tmp_wk7ote9']
[2024-04-07T11:01:02.251+0000] {standard_task_runner.py:88} INFO - Job 362: Subtask establish_database_conn
[2024-04-07T11:01:02.287+0000] {logging_mixin.py:188} WARNING - /home/***/.local/lib/python3.8/site-packages/***/settings.py:195 DeprecationWarning: The sql_alchemy_conn option in [core] has been moved to the sql_alchemy_conn option in [database] - the old setting has been used, but please update your config.
[2024-04-07T11:01:02.393+0000] {task_command.py:423} INFO - Running <TaskInstance: defi_data_pipeline.establish_database_conn scheduled__2024-04-07T10:01:00+00:00 [running]> on host aa86d21a7ebc
[2024-04-07T11:01:02.561+0000] {taskinstance.py:2481} INFO - Exporting env vars: AIRFLOW_CTX_DAG_OWNER='***' AIRFLOW_CTX_DAG_ID='defi_data_pipeline' AIRFLOW_CTX_TASK_ID='establish_database_conn' AIRFLOW_CTX_EXECUTION_DATE='2024-04-07T10:01:00+00:00' AIRFLOW_CTX_TRY_NUMBER='1' AIRFLOW_CTX_DAG_RUN_ID='scheduled__2024-04-07T10:01:00+00:00'
[2024-04-07T11:01:02.593+0000] {base.py:83} INFO - Using connection ID 'defi_connection' for task execution.
[2024-04-07T11:01:02.595+0000] {taskinstance.py:2699} ERROR - Task failed with exception
Traceback (most recent call last):
  File "/home/airflow/.local/lib/python3.8/site-packages/airflow/models/taskinstance.py", line 433, in _execute_task
    result = execute_callable(context=context, **execute_callable_kwargs)
  File "/home/airflow/.local/lib/python3.8/site-packages/airflow/decorators/base.py", line 242, in execute
    return_value = super().execute(context)
  File "/home/airflow/.local/lib/python3.8/site-packages/airflow/operators/python.py", line 199, in execute
    return_value = self.execute_callable()
  File "/home/airflow/.local/lib/python3.8/site-packages/airflow/operators/python.py", line 216, in execute_callable
    return self.python_callable(*self.op_args, **self.op_kwargs)
  File "/opt/airflow/dags/_etl.py", line 70, in establish_database_conn
    conn = hook.get_conn()
  File "/home/airflow/.local/lib/python3.8/site-packages/airflow/providers/postgres/hooks/postgres.py", line 158, in get_conn
    self.conn = psycopg2.connect(**conn_args)
  File "/home/airflow/.local/lib/python3.8/site-packages/psycopg2/__init__.py", line 122, in connect
    conn = _connect(dsn, connection_factory=connection_factory, **kwasync)
psycopg2.OperationalError: connection to server at "localhost" (127.0.0.1), port 5432 failed: Connection refused
	Is the server running on that host and accepting TCP/IP connections?
connection to server at "localhost" (::1), port 5432 failed: Cannot assign requested address
	Is the server running on that host and accepting TCP/IP connections?

[2024-04-07T11:01:02.614+0000] {taskinstance.py:1138} INFO - Marking task as FAILED. dag_id=defi_data_pipeline, task_id=establish_database_conn, execution_date=20240407T100100, start_date=20240407T110101, end_date=20240407T110102
[2024-04-07T11:01:02.658+0000] {standard_task_runner.py:107} ERROR - Failed to execute job 362 for task establish_database_conn (connection to server at "localhost" (127.0.0.1), port 5432 failed: Connection refused
	Is the server running on that host and accepting TCP/IP connections?
connection to server at "localhost" (::1), port 5432 failed: Cannot assign requested address
	Is the server running on that host and accepting TCP/IP connections?
; 30854)
[2024-04-07T11:01:02.678+0000] {local_task_job_runner.py:234} INFO - Task exited with return code 1
[2024-04-07T11:01:02.708+0000] {taskinstance.py:3281} INFO - 0 downstream tasks scheduled from follow-on schedule check
[2024-04-07T11:24:36.135+0000] {taskinstance.py:1957} INFO - Dependencies all met for dep_context=non-requeueable deps ti=<TaskInstance: defi_data_pipeline.establish_database_conn scheduled__2024-04-07T10:01:00+00:00 [queued]>
[2024-04-07T11:24:36.309+0000] {taskinstance.py:1957} INFO - Dependencies all met for dep_context=requeueable deps ti=<TaskInstance: defi_data_pipeline.establish_database_conn scheduled__2024-04-07T10:01:00+00:00 [queued]>
[2024-04-07T11:24:36.310+0000] {taskinstance.py:2171} INFO - Starting attempt 1 of 1
[2024-04-07T11:24:37.080+0000] {taskinstance.py:2192} INFO - Executing <Task(_PythonDecoratedOperator): establish_database_conn> on 2024-04-07 10:01:00+00:00
[2024-04-07T11:24:37.101+0000] {standard_task_runner.py:60} INFO - Started process 32350 to run task
[2024-04-07T11:24:37.121+0000] {standard_task_runner.py:87} INFO - Running: ['***', 'tasks', 'run', 'defi_data_pipeline', 'establish_database_conn', 'scheduled__2024-04-07T10:01:00+00:00', '--job-id', '365', '--raw', '--subdir', 'DAGS_FOLDER/_etl.py', '--cfg-path', '/tmp/tmps2lhnc5a']
[2024-04-07T11:24:37.128+0000] {standard_task_runner.py:88} INFO - Job 365: Subtask establish_database_conn
[2024-04-07T11:24:37.227+0000] {logging_mixin.py:188} WARNING - /home/***/.local/lib/python3.8/site-packages/***/settings.py:195 DeprecationWarning: The sql_alchemy_conn option in [core] has been moved to the sql_alchemy_conn option in [database] - the old setting has been used, but please update your config.
[2024-04-07T11:24:37.364+0000] {task_command.py:423} INFO - Running <TaskInstance: defi_data_pipeline.establish_database_conn scheduled__2024-04-07T10:01:00+00:00 [running]> on host aa86d21a7ebc
[2024-04-07T11:24:37.594+0000] {taskinstance.py:2481} INFO - Exporting env vars: AIRFLOW_CTX_DAG_OWNER='***' AIRFLOW_CTX_DAG_ID='defi_data_pipeline' AIRFLOW_CTX_TASK_ID='establish_database_conn' AIRFLOW_CTX_EXECUTION_DATE='2024-04-07T10:01:00+00:00' AIRFLOW_CTX_TRY_NUMBER='1' AIRFLOW_CTX_DAG_RUN_ID='scheduled__2024-04-07T10:01:00+00:00'
[2024-04-07T11:24:37.647+0000] {base.py:83} INFO - Using connection ID 'defi_connection' for task execution.
[2024-04-07T11:24:37.650+0000] {taskinstance.py:2699} ERROR - Task failed with exception
Traceback (most recent call last):
  File "/home/airflow/.local/lib/python3.8/site-packages/airflow/models/taskinstance.py", line 433, in _execute_task
    result = execute_callable(context=context, **execute_callable_kwargs)
  File "/home/airflow/.local/lib/python3.8/site-packages/airflow/decorators/base.py", line 242, in execute
    return_value = super().execute(context)
  File "/home/airflow/.local/lib/python3.8/site-packages/airflow/operators/python.py", line 199, in execute
    return_value = self.execute_callable()
  File "/home/airflow/.local/lib/python3.8/site-packages/airflow/operators/python.py", line 216, in execute_callable
    return self.python_callable(*self.op_args, **self.op_kwargs)
  File "/opt/airflow/dags/_etl.py", line 70, in establish_database_conn
    conn = hook.get_conn()
  File "/home/airflow/.local/lib/python3.8/site-packages/airflow/providers/postgres/hooks/postgres.py", line 158, in get_conn
    self.conn = psycopg2.connect(**conn_args)
  File "/home/airflow/.local/lib/python3.8/site-packages/psycopg2/__init__.py", line 122, in connect
    conn = _connect(dsn, connection_factory=connection_factory, **kwasync)
psycopg2.OperationalError: connection to server at "localhost" (127.0.0.1), port 5432 failed: Connection refused
	Is the server running on that host and accepting TCP/IP connections?
connection to server at "localhost" (::1), port 5432 failed: Cannot assign requested address
	Is the server running on that host and accepting TCP/IP connections?

[2024-04-07T11:24:37.699+0000] {taskinstance.py:1138} INFO - Marking task as FAILED. dag_id=defi_data_pipeline, task_id=establish_database_conn, execution_date=20240407T100100, start_date=20240407T112436, end_date=20240407T112437
[2024-04-07T11:24:37.739+0000] {standard_task_runner.py:107} ERROR - Failed to execute job 365 for task establish_database_conn (connection to server at "localhost" (127.0.0.1), port 5432 failed: Connection refused
	Is the server running on that host and accepting TCP/IP connections?
connection to server at "localhost" (::1), port 5432 failed: Cannot assign requested address
	Is the server running on that host and accepting TCP/IP connections?
; 32350)
[2024-04-07T11:24:37.770+0000] {local_task_job_runner.py:234} INFO - Task exited with return code 1
[2024-04-07T11:24:37.811+0000] {taskinstance.py:3281} INFO - 0 downstream tasks scheduled from follow-on schedule check
[2024-04-07T11:33:43.346+0000] {taskinstance.py:1957} INFO - Dependencies all met for dep_context=non-requeueable deps ti=<TaskInstance: defi_data_pipeline.establish_database_conn scheduled__2024-04-07T10:01:00+00:00 [queued]>
[2024-04-07T11:33:43.367+0000] {taskinstance.py:1957} INFO - Dependencies all met for dep_context=requeueable deps ti=<TaskInstance: defi_data_pipeline.establish_database_conn scheduled__2024-04-07T10:01:00+00:00 [queued]>
[2024-04-07T11:33:43.368+0000] {taskinstance.py:2171} INFO - Starting attempt 1 of 1
[2024-04-07T11:33:45.052+0000] {taskinstance.py:2192} INFO - Executing <Task(_PythonDecoratedOperator): establish_database_conn> on 2024-04-07 10:01:00+00:00
[2024-04-07T11:33:45.061+0000] {standard_task_runner.py:60} INFO - Started process 32927 to run task
[2024-04-07T11:33:45.066+0000] {standard_task_runner.py:87} INFO - Running: ['***', 'tasks', 'run', 'defi_data_pipeline', 'establish_database_conn', 'scheduled__2024-04-07T10:01:00+00:00', '--job-id', '369', '--raw', '--subdir', 'DAGS_FOLDER/_etl.py', '--cfg-path', '/tmp/tmpb1x1z388']
[2024-04-07T11:33:45.072+0000] {standard_task_runner.py:88} INFO - Job 369: Subtask establish_database_conn
[2024-04-07T11:33:45.130+0000] {logging_mixin.py:188} WARNING - /home/***/.local/lib/python3.8/site-packages/***/settings.py:195 DeprecationWarning: The sql_alchemy_conn option in [core] has been moved to the sql_alchemy_conn option in [database] - the old setting has been used, but please update your config.
[2024-04-07T11:33:45.217+0000] {task_command.py:423} INFO - Running <TaskInstance: defi_data_pipeline.establish_database_conn scheduled__2024-04-07T10:01:00+00:00 [running]> on host aa86d21a7ebc
[2024-04-07T11:33:45.412+0000] {taskinstance.py:2481} INFO - Exporting env vars: AIRFLOW_CTX_DAG_OWNER='***' AIRFLOW_CTX_DAG_ID='defi_data_pipeline' AIRFLOW_CTX_TASK_ID='establish_database_conn' AIRFLOW_CTX_EXECUTION_DATE='2024-04-07T10:01:00+00:00' AIRFLOW_CTX_TRY_NUMBER='1' AIRFLOW_CTX_DAG_RUN_ID='scheduled__2024-04-07T10:01:00+00:00'
[2024-04-07T11:33:45.437+0000] {base.py:83} INFO - Using connection ID 'defi_connection' for task execution.
[2024-04-07T11:33:45.440+0000] {taskinstance.py:2699} ERROR - Task failed with exception
Traceback (most recent call last):
  File "/home/airflow/.local/lib/python3.8/site-packages/airflow/models/taskinstance.py", line 433, in _execute_task
    result = execute_callable(context=context, **execute_callable_kwargs)
  File "/home/airflow/.local/lib/python3.8/site-packages/airflow/decorators/base.py", line 242, in execute
    return_value = super().execute(context)
  File "/home/airflow/.local/lib/python3.8/site-packages/airflow/operators/python.py", line 199, in execute
    return_value = self.execute_callable()
  File "/home/airflow/.local/lib/python3.8/site-packages/airflow/operators/python.py", line 216, in execute_callable
    return self.python_callable(*self.op_args, **self.op_kwargs)
  File "/opt/airflow/dags/_etl.py", line 70, in establish_database_conn
    conn = hook.get_conn()
  File "/home/airflow/.local/lib/python3.8/site-packages/airflow/providers/postgres/hooks/postgres.py", line 158, in get_conn
    self.conn = psycopg2.connect(**conn_args)
  File "/home/airflow/.local/lib/python3.8/site-packages/psycopg2/__init__.py", line 122, in connect
    conn = _connect(dsn, connection_factory=connection_factory, **kwasync)
psycopg2.OperationalError: connection to server at "localhost" (127.0.0.1), port 5432 failed: Connection refused
	Is the server running on that host and accepting TCP/IP connections?
connection to server at "localhost" (::1), port 5432 failed: Cannot assign requested address
	Is the server running on that host and accepting TCP/IP connections?

[2024-04-07T11:33:45.465+0000] {taskinstance.py:1138} INFO - Marking task as FAILED. dag_id=defi_data_pipeline, task_id=establish_database_conn, execution_date=20240407T100100, start_date=20240407T113343, end_date=20240407T113345
[2024-04-07T11:33:45.500+0000] {standard_task_runner.py:107} ERROR - Failed to execute job 369 for task establish_database_conn (connection to server at "localhost" (127.0.0.1), port 5432 failed: Connection refused
	Is the server running on that host and accepting TCP/IP connections?
connection to server at "localhost" (::1), port 5432 failed: Cannot assign requested address
	Is the server running on that host and accepting TCP/IP connections?
; 32927)
[2024-04-07T11:33:45.535+0000] {local_task_job_runner.py:234} INFO - Task exited with return code 1
[2024-04-07T11:33:45.558+0000] {taskinstance.py:3281} INFO - 0 downstream tasks scheduled from follow-on schedule check
