[2024-04-07T12:01:06.551+0000] {taskinstance.py:1957} INFO - Dependencies all met for dep_context=non-requeueable deps ti=<TaskInstance: defi_data_pipeline.establish_database_conn scheduled__2024-04-07T11:01:00+00:00 [queued]>
[2024-04-07T12:01:06.573+0000] {taskinstance.py:1957} INFO - Dependencies all met for dep_context=requeueable deps ti=<TaskInstance: defi_data_pipeline.establish_database_conn scheduled__2024-04-07T11:01:00+00:00 [queued]>
[2024-04-07T12:01:06.573+0000] {taskinstance.py:2171} INFO - Starting attempt 1 of 1
[2024-04-07T12:01:06.811+0000] {taskinstance.py:2192} INFO - Executing <Task(_PythonDecoratedOperator): establish_database_conn> on 2024-04-07 11:01:00+00:00
[2024-04-07T12:01:06.818+0000] {standard_task_runner.py:60} INFO - Started process 34726 to run task
[2024-04-07T12:01:06.824+0000] {standard_task_runner.py:87} INFO - Running: ['***', 'tasks', 'run', 'defi_data_pipeline', 'establish_database_conn', 'scheduled__2024-04-07T11:01:00+00:00', '--job-id', '376', '--raw', '--subdir', 'DAGS_FOLDER/_etl.py', '--cfg-path', '/tmp/tmpcwuomdji']
[2024-04-07T12:01:06.828+0000] {standard_task_runner.py:88} INFO - Job 376: Subtask establish_database_conn
[2024-04-07T12:01:06.853+0000] {logging_mixin.py:188} WARNING - /home/***/.local/lib/python3.8/site-packages/***/settings.py:195 DeprecationWarning: The sql_alchemy_conn option in [core] has been moved to the sql_alchemy_conn option in [database] - the old setting has been used, but please update your config.
[2024-04-07T12:01:06.908+0000] {task_command.py:423} INFO - Running <TaskInstance: defi_data_pipeline.establish_database_conn scheduled__2024-04-07T11:01:00+00:00 [running]> on host aa86d21a7ebc
[2024-04-07T12:01:07.236+0000] {taskinstance.py:2481} INFO - Exporting env vars: AIRFLOW_CTX_DAG_OWNER='***' AIRFLOW_CTX_DAG_ID='defi_data_pipeline' AIRFLOW_CTX_TASK_ID='establish_database_conn' AIRFLOW_CTX_EXECUTION_DATE='2024-04-07T11:01:00+00:00' AIRFLOW_CTX_TRY_NUMBER='1' AIRFLOW_CTX_DAG_RUN_ID='scheduled__2024-04-07T11:01:00+00:00'
[2024-04-07T12:01:07.254+0000] {base.py:83} INFO - Using connection ID 'defi_connection' for task execution.
[2024-04-07T12:01:07.264+0000] {taskinstance.py:2699} ERROR - Task failed with exception
Traceback (most recent call last):
  File "/home/airflow/.local/lib/python3.8/site-packages/airflow/models/taskinstance.py", line 433, in _execute_task
    result = execute_callable(context=context, **execute_callable_kwargs)
  File "/home/airflow/.local/lib/python3.8/site-packages/airflow/decorators/base.py", line 242, in execute
    return_value = super().execute(context)
  File "/home/airflow/.local/lib/python3.8/site-packages/airflow/operators/python.py", line 199, in execute
    return_value = self.execute_callable()
  File "/home/airflow/.local/lib/python3.8/site-packages/airflow/operators/python.py", line 216, in execute_callable
    return self.python_callable(*self.op_args, **self.op_kwargs)
  File "/opt/airflow/dags/_etl.py", line 87, in establish_database_conn
    conn = hook.get_conn()
  File "/home/airflow/.local/lib/python3.8/site-packages/airflow/providers/postgres/hooks/postgres.py", line 158, in get_conn
    self.conn = psycopg2.connect(**conn_args)
  File "/home/airflow/.local/lib/python3.8/site-packages/psycopg2/__init__.py", line 122, in connect
    conn = _connect(dsn, connection_factory=connection_factory, **kwasync)
psycopg2.OperationalError: connection to server at "localhost" (127.0.0.1), port 5432 failed: Connection refused
	Is the server running on that host and accepting TCP/IP connections?
connection to server at "localhost" (::1), port 5432 failed: Cannot assign requested address
	Is the server running on that host and accepting TCP/IP connections?

[2024-04-07T12:01:07.292+0000] {taskinstance.py:1138} INFO - Marking task as FAILED. dag_id=defi_data_pipeline, task_id=establish_database_conn, execution_date=20240407T110100, start_date=20240407T120106, end_date=20240407T120107
[2024-04-07T12:01:07.338+0000] {standard_task_runner.py:107} ERROR - Failed to execute job 376 for task establish_database_conn (connection to server at "localhost" (127.0.0.1), port 5432 failed: Connection refused
	Is the server running on that host and accepting TCP/IP connections?
connection to server at "localhost" (::1), port 5432 failed: Cannot assign requested address
	Is the server running on that host and accepting TCP/IP connections?
; 34726)
[2024-04-07T12:01:07.364+0000] {local_task_job_runner.py:234} INFO - Task exited with return code 1
[2024-04-07T12:01:07.394+0000] {taskinstance.py:3281} INFO - 0 downstream tasks scheduled from follow-on schedule check
[2024-04-07T12:21:01.389+0000] {taskinstance.py:1957} INFO - Dependencies all met for dep_context=non-requeueable deps ti=<TaskInstance: defi_data_pipeline.establish_database_conn scheduled__2024-04-07T11:01:00+00:00 [queued]>
[2024-04-07T12:21:01.401+0000] {taskinstance.py:1957} INFO - Dependencies all met for dep_context=requeueable deps ti=<TaskInstance: defi_data_pipeline.establish_database_conn scheduled__2024-04-07T11:01:00+00:00 [queued]>
[2024-04-07T12:21:01.402+0000] {taskinstance.py:2171} INFO - Starting attempt 1 of 1
[2024-04-07T12:21:01.628+0000] {taskinstance.py:2192} INFO - Executing <Task(_PythonDecoratedOperator): establish_database_conn> on 2024-04-07 11:01:00+00:00
[2024-04-07T12:21:01.636+0000] {standard_task_runner.py:60} INFO - Started process 35965 to run task
[2024-04-07T12:21:01.640+0000] {standard_task_runner.py:87} INFO - Running: ['***', 'tasks', 'run', 'defi_data_pipeline', 'establish_database_conn', 'scheduled__2024-04-07T11:01:00+00:00', '--job-id', '385', '--raw', '--subdir', 'DAGS_FOLDER/_etl.py', '--cfg-path', '/tmp/tmpsjj4nsv3']
[2024-04-07T12:21:01.644+0000] {standard_task_runner.py:88} INFO - Job 385: Subtask establish_database_conn
[2024-04-07T12:21:01.670+0000] {logging_mixin.py:188} WARNING - /home/***/.local/lib/python3.8/site-packages/***/settings.py:195 DeprecationWarning: The sql_alchemy_conn option in [core] has been moved to the sql_alchemy_conn option in [database] - the old setting has been used, but please update your config.
[2024-04-07T12:21:01.726+0000] {task_command.py:423} INFO - Running <TaskInstance: defi_data_pipeline.establish_database_conn scheduled__2024-04-07T11:01:00+00:00 [running]> on host aa86d21a7ebc
[2024-04-07T12:21:01.917+0000] {taskinstance.py:2481} INFO - Exporting env vars: AIRFLOW_CTX_DAG_OWNER='***' AIRFLOW_CTX_DAG_ID='defi_data_pipeline' AIRFLOW_CTX_TASK_ID='establish_database_conn' AIRFLOW_CTX_EXECUTION_DATE='2024-04-07T11:01:00+00:00' AIRFLOW_CTX_TRY_NUMBER='1' AIRFLOW_CTX_DAG_RUN_ID='scheduled__2024-04-07T11:01:00+00:00'
[2024-04-07T12:21:01.936+0000] {base.py:83} INFO - Using connection ID 'defi_connection' for task execution.
[2024-04-07T12:21:01.945+0000] {taskinstance.py:2699} ERROR - Task failed with exception
Traceback (most recent call last):
  File "/home/airflow/.local/lib/python3.8/site-packages/airflow/models/taskinstance.py", line 433, in _execute_task
    result = execute_callable(context=context, **execute_callable_kwargs)
  File "/home/airflow/.local/lib/python3.8/site-packages/airflow/decorators/base.py", line 242, in execute
    return_value = super().execute(context)
  File "/home/airflow/.local/lib/python3.8/site-packages/airflow/operators/python.py", line 199, in execute
    return_value = self.execute_callable()
  File "/home/airflow/.local/lib/python3.8/site-packages/airflow/operators/python.py", line 216, in execute_callable
    return self.python_callable(*self.op_args, **self.op_kwargs)
  File "/opt/airflow/dags/_etl.py", line 92, in establish_database_conn
    cursor.execute(qry, d)
TypeError: string indices must be integers
[2024-04-07T12:21:01.962+0000] {taskinstance.py:1138} INFO - Marking task as FAILED. dag_id=defi_data_pipeline, task_id=establish_database_conn, execution_date=20240407T110100, start_date=20240407T122101, end_date=20240407T122101
[2024-04-07T12:21:01.986+0000] {standard_task_runner.py:107} ERROR - Failed to execute job 385 for task establish_database_conn (string indices must be integers; 35965)
[2024-04-07T12:21:02.014+0000] {local_task_job_runner.py:234} INFO - Task exited with return code 1
[2024-04-07T12:21:02.034+0000] {taskinstance.py:3281} INFO - 0 downstream tasks scheduled from follow-on schedule check
[2024-04-07T12:37:06.945+0000] {taskinstance.py:1957} INFO - Dependencies all met for dep_context=non-requeueable deps ti=<TaskInstance: defi_data_pipeline.establish_database_conn scheduled__2024-04-07T11:01:00+00:00 [queued]>
[2024-04-07T12:37:06.983+0000] {taskinstance.py:1957} INFO - Dependencies all met for dep_context=requeueable deps ti=<TaskInstance: defi_data_pipeline.establish_database_conn scheduled__2024-04-07T11:01:00+00:00 [queued]>
[2024-04-07T12:37:06.985+0000] {taskinstance.py:2171} INFO - Starting attempt 1 of 1
[2024-04-07T12:37:07.760+0000] {taskinstance.py:2192} INFO - Executing <Task(_PythonDecoratedOperator): establish_database_conn> on 2024-04-07 11:01:00+00:00
[2024-04-07T12:37:07.781+0000] {standard_task_runner.py:60} INFO - Started process 37050 to run task
[2024-04-07T12:37:07.790+0000] {standard_task_runner.py:87} INFO - Running: ['***', 'tasks', 'run', 'defi_data_pipeline', 'establish_database_conn', 'scheduled__2024-04-07T11:01:00+00:00', '--job-id', '394', '--raw', '--subdir', 'DAGS_FOLDER/_etl.py', '--cfg-path', '/tmp/tmpf4xyqq2r']
[2024-04-07T12:37:07.797+0000] {standard_task_runner.py:88} INFO - Job 394: Subtask establish_database_conn
[2024-04-07T12:37:07.844+0000] {logging_mixin.py:188} WARNING - /home/***/.local/lib/python3.8/site-packages/***/settings.py:195 DeprecationWarning: The sql_alchemy_conn option in [core] has been moved to the sql_alchemy_conn option in [database] - the old setting has been used, but please update your config.
[2024-04-07T12:37:07.910+0000] {task_command.py:423} INFO - Running <TaskInstance: defi_data_pipeline.establish_database_conn scheduled__2024-04-07T11:01:00+00:00 [running]> on host aa86d21a7ebc
[2024-04-07T12:37:08.492+0000] {taskinstance.py:2481} INFO - Exporting env vars: AIRFLOW_CTX_DAG_OWNER='***' AIRFLOW_CTX_DAG_ID='defi_data_pipeline' AIRFLOW_CTX_TASK_ID='establish_database_conn' AIRFLOW_CTX_EXECUTION_DATE='2024-04-07T11:01:00+00:00' AIRFLOW_CTX_TRY_NUMBER='1' AIRFLOW_CTX_DAG_RUN_ID='scheduled__2024-04-07T11:01:00+00:00'
[2024-04-07T12:37:08.637+0000] {base.py:83} INFO - Using connection ID 'defi_connection' for task execution.
[2024-04-07T12:37:08.682+0000] {taskinstance.py:2699} ERROR - Task failed with exception
Traceback (most recent call last):
  File "/home/airflow/.local/lib/python3.8/site-packages/airflow/models/taskinstance.py", line 433, in _execute_task
    result = execute_callable(context=context, **execute_callable_kwargs)
  File "/home/airflow/.local/lib/python3.8/site-packages/airflow/decorators/base.py", line 242, in execute
    return_value = super().execute(context)
  File "/home/airflow/.local/lib/python3.8/site-packages/airflow/operators/python.py", line 199, in execute
    return_value = self.execute_callable()
  File "/home/airflow/.local/lib/python3.8/site-packages/airflow/operators/python.py", line 216, in execute_callable
    return self.python_callable(*self.op_args, **self.op_kwargs)
  File "/opt/airflow/dags/_etl.py", line 83, in establish_database_conn
    cursor.execute(qry, (record))
TypeError: not all arguments converted during string formatting
[2024-04-07T12:37:08.733+0000] {taskinstance.py:1138} INFO - Marking task as FAILED. dag_id=defi_data_pipeline, task_id=establish_database_conn, execution_date=20240407T110100, start_date=20240407T123706, end_date=20240407T123708
[2024-04-07T12:37:08.820+0000] {standard_task_runner.py:107} ERROR - Failed to execute job 394 for task establish_database_conn (not all arguments converted during string formatting; 37050)
[2024-04-07T12:37:08.894+0000] {local_task_job_runner.py:234} INFO - Task exited with return code 1
[2024-04-07T12:37:08.944+0000] {taskinstance.py:3281} INFO - 0 downstream tasks scheduled from follow-on schedule check
